SampleOutput/sample_vwap_6.txt
XBUY: 16.5865
NRGX: 20.4516
CFG-D: 24.9331
ZYNE: 5.0659
ZYME: 15.3608
ZXZZT: 6.6666
ZVZZT: 9.9895
ZUO: 21.2555
ZUMZ: 25.1025
ZTS: 85.2794
ZTR: 9.7628
ZTO: 17.0208
ZSL: 34.8844
ZSAN: 2.2715
ZS: 45.4668
ZROZ: 74.7242
ZOM: 0.6443
ZNH: 32.9738
ZNGA: 4.4811
ZN: 0.4811
ZMLP: 9.0533
ZLAB: 26.8964
ZKIN: 1.5452
ZJZZT: 6.6666
ZIXI: 7.4853
ZIV: 66.7552
ZIOP: 2.0663
ZIONW: 10.7799
ZION: 48.337
ZGNX: 41.6949
ZG: 32.9543
ZFGN: 4.2402
ZF: 8.7571
ZEUS: 18.6787
ZEN: 65.3672
ZEAL: 14.2007
ZDGE: 1.2933
ZBRA: 171.1351
ZBIO: 15.9316
ZBH: 107.549
ZB-G: 26.84
ZAYO: 26.7182
ZAGG: 11.218
Z: 33.2425
YYY: 16.542
YY: 67.2023
YXI: 19.3333
YVR: 1.5666
YUMC: 35.7589
YUMA: 0.1133
YUM: 93.2184
YTRA: 5.1026
YTEN: 0.8056
YRIV: 2.0735
YRD: 10.9871
YRCW: 5.808
YPF: 15.8121
YORW: 31.8244
YOGA: 0.5185
YNDX: 33.0636
YMLP: 19.35
YMLI: 8.2466
YMAB: 19.6864
YLDE: 18.3266
YLCO: 12.1471
YINN: 21.7288
YIN: 6.9511
YI: 8.9865
YGYI: 7.3126
YEXT: 14.9856
YETI: 16.7833
YELP: 36.1856
YCS: 61.8867
YANG: 52.1043
Y: 623.9366
XYL: 70.9148
XYF: 5.36
XXII: 2.287
XWEB: 84.7414
XTN: 39.7815
XTL: 65.0421
XT: 35.6554
XSW: 75.9357
XSPA: 0.1827
XSOE: 25.7025
XSLV: 45.7805
XSD: 69.6236
XRX: 27.8556
XRT: 44.0142
XRLV: 22.7399
XRAY: 41.2538
XPP: 65.7765
XPO: 61.5623
XPL: 0.184
XPH: 38.5133
XPER: 21.1126
XOP: 30.6268
XONE: 8.4076
XON: 7.5162
XOMA: 12.0132
XOM: 71.98
XOG: 4.0764
XNTK: 52.752
XNET: 3.4064
XNCR: 32.5288
XMLV: 45.557
XME: 30.1298
XLY: 107.2018
XLV: 88.9669
XLU: 53.4968
XLRN: 40.1797
XLRE: 33.9397
XLP: 52.2841
XLNX: 111.4487
XLK: 65.7974
XLI: 71.1144
XLG: 185.7218
XLF: 25.9697
XLE: 63.0125
XLC: 43.9078
XLB: 53.9759
XKST: 26.5
XITK: 92.5633
XIN: 4.7641
XHS: 45.6399
XHR: 18.637
XHE: 71.8581
XHB: 35.717
XGTI: 0.3699
XFLT: 8.4626
XES: 10.9142
XERS: 14.9745
XENT: 28.9552
XENE: 7.9648
XELB: 1.1876
XELA: 3.599
XEL: 50.9522
XEC: 75.8731
XCEM: 17.2466
XBIT: 6.4448
XBIO: 2.1381
XBI: 80.7598
XAR: 88.681
XAN-C: 24.9933
XAN: 10.5114
X: 22.2285
WYY: 0.4399
WYNN: 119.9024
WYND: 42.365
WY: 26.126
WWW: 33.9273
WWR: 0.1425
WWE: 82.4341
WWD: 85.9414
WVVIP: 3.0799
WVVI: 4.7066
WVFC: 9.6733
WVE: 35.5649
WUBA: 61.1806
WU: 18.2693
WTW: 31.8259
WTTR: 8.5927
WTS: 73.2986
WTRH: 12.1399
WTR: 34.2874
WTMF: 25.5999
WTM: 892.0455
WTIU: 13.7796
WTID: 9.7636
WTI: 5.0709
WTFCM: 24.9756
WTFC: 72.5624
WTER: 3.5011
WTBA: 21.6109
WSTL: 1.8205
WST: 105.558
WSR: 14.2428
WSO: 146.0898
WSM: 52.5121
WSFS: 42.0483
WSC: 10.125
WSBF: 16.6701
WSBC: 41.5539
WRTC: 2.8115
WRN: 0.7288
WRLSR: 0.2539
WRLS: 10.2
WRLD: 110.4147
WRK: 41.3464
WRI: 28.4339
WRE: 25.1628
WRD: 17.1855
WRB-E: 23.9759
WRB-D: 16.4116
WRB-C: 25.2104
WRB-B: 24.5272
WRB: 76.9949
WPX: 12.275
WPS: 36.6051
WPRT: 1.4817
WPP: 57.7072
WPM: 20.3652
WPG-I: 10.1866
WPG-H: 10.4999
WPG: 5.7641
WPC: 73.9461
WP: 84.0831
WOW: 7.2433
WOR: 36.8218
WOOD: 66.202
WNS: 48.9136
WNEB: 9.2871
WNC: 13.9836
WMT: 94.8945
WMS: 24.9996
WMK: 47.8044
WMGIZ: 0.0046
WMGI: 29.7701
WMC: 9.5903
WMB: 26.8979
WM: 94.6044
WLTW: 160.209
WLL: 28.8063
WLKP: 18.9935
WLK: 76.1513
WLH: 12.3853
WLFC: 34.5177
WLDN: 32.5367
WKHS: 0.8858
WK: 39.2848
WIX: 105.7365
WIW: 10.0573
WIT: 5.4864
WISA: 2.627
WIRE: 52.8752
WIP: 35.9212
WINS: 23.7696
WING: 66.1372
WINA: 152.912
WIN: 2.8591
WILC: 5.4266
WIL: 42.9666
WIFI: 22.8607
WIA: 10.9305
WHR: 131.0423
WHLRW: 0.0068
WHLRP: 10.2934
WHLRD: 11.8366
WHLR: 1.6755
WHLM: 3.4999
WHG: 36.4043
WHF: 13.4468
WHD: 32.4038
WH: 49.6627
WGP: 32.6712
WGO: 29.3969
WFT: 0.6427
WFHY: 32.9333
WFE-A: 24.3099
WFC-Y: 24.6365
WFC-X: 22.3759
WFC-W: 23.5535
WFC-V: 25.8144
WFC-T: 17.1933
WFC-R: 18.4815
WFC-Q: 20.9374
WFC-P: 20.3304
WFC-O: 23.0381
WFC-N: 21.9436
WFC-L: 862.4133
WFC: 50.0032
WEYS: 23.857
WEX: 157.6821
WETF: 6.5041
WES: 49.8977
WERN: 33.1803
WEN: 17.3235
WELL-I: 67.3824
WELL: 76.5687
WEC: 71.0764
WEBK: 19.4033
WEAT: 6.027
WEA: 12.5025
WDRW: 30.5955
WDR: 16.8386
WDIV: 65.36
WDFC: 178.2454
WDC: 43.0469
WDAY: 169.7836
WD: 47.898
WCN: 81.4014
WCHN: 16.8933
WCG: 275.322
WCFB: 5.5666
WCC: 53.6369
WBT: 13.8411
WBS-F: 19.0788
WBS: 55.9441
WBK: 18.2493
WBIY: 15.8999
WBIR: 15.4666
WBII: 16.1399
WBIH: 21.9714
WBIG: 15.5599
WBID: 20.95
WBIB: 21.24
WBC: 113.0611
WBAI: 14.3018
WBA: 71.637
WB: 58.3169
WATT: 7.3603
WAT: 230.3952
WASH: 51.6977
WAL: 45.546
WAIR: 8.0979
WAGE: 30.8139
WAFD: 29.2156
WABC: 62.9502
WAB: 68.5088
WAAS: 20.9769
W: 107.5891
VZA: 25.3286
VZ: 53.3107
VYMI: 54.7604
VYM: 81.7736
VYGR: 10.4889
VXZB: 20.0749
VXXB: 37.8703
VXUS: 50.4527
VXRT: 1.8231
VXF: 109.6275
VWOB: 75.2962
VWO: 40.928
VVV: 22.3848
VVUS: 4.7149
VVR: 3.7918
VVPR: 0.6466
VVI: 51.8404
VVC: 72.2765
VV: 122.4926
VUZI: 4.0359
VUSE: 28.7751
VUG: 143.866
VTWV: 91.7892
VTWO: 117.8811
VTWG: 133.6429
VTVT: 2.7178
VTV: 103.6191
VTSI: 3.9041
VTR: 63.9012
VTNR: 1.2722
VTN: 12.6228
VTL: 0.1953
VTIQU: 6.8666
VTIP: 48.084
VTI: 136.7553
VTHR: 119.2135
VTGN: 1.5312
VTEB: 51.0982
VTC: 71.2911
VTA: 10.6977
VT: 69.9197
VSTO: 10.3239
VSTM: 3.1215
VST: 24.9036
VSS: 100.7612
VSMV: 28.1027
VSM: 37.0917
VSLR: 4.0121
VSI: 4.5797
VSH: 19.1471
VSGX: 31.8266
VSEC: 32.1685
VSAT: 61.4152
VRTX: 186.0561
VRTV: 33.227
VRTU: 47.7338
VRTSP: 76.3837
VRTS: 87.2561
VRSN: 166.0878
VRSK: 117.2474
VRS: 24.7106
VRRM: 10.2713
VRP: 22.5843
VRNT: 47.0803
VRNS: 57.468
VRNA: 4.6377
VRML: 0.6854
VRIG: 20.995
VREX: 27.9813
VRCA: 11.9466
VRAY: 6.9247
VRA: 8.9507
VPV: 12.0451
VPU: 119.6404
VPL: 64.5433
VPG: 32.0248
VOYA: 45.9437
VOXX: 5.1882
VOX: 78.341
VOT: 131.0206
VOOV: 105.0515
VOOG: 141.5742
VOO: 244.5301
VONV: 103.7164
VONG: 143.9031
VONE: 122.2152
VOE: 103.7219
VOD: 17.8472
VOC: 3.6181
VO: 151.3124
VNTR: 4.6473
VNRX: 2.5525
VNQI: 57.057
VNQ: 82.4498
VNOM: 30.515
VNO-M: 15.1533
VNO-L: 21.3263
VNO: 68.6654
VNM: 15.7882
VNLA: 49.344
VNET: 8.7098
VNE: 29.2834
VNDA: 28.2979
VNCE: 11.6927
VMW: 146.0488
VMOT: 16.7666
VMO: 11.6548
VMM: 12.17
VMI: 126.6817
VMC: 101.5742
VMBS: 51.6707
VLYPP: 24.5248
VLYPO: 22.3682
VLY: 10.2989
VLUE: 78.625
VLT: 13.7657
VLRX: 0.3986
VLRS: 7.4241
VLO: 82.5338
VLGEA: 26.0167
VKTXW: 4.4239
VKTX: 8.0838
VKQ: 11.7635
VKI: 8.9508
VJET: 1.3866
VIXY: 31.1205
VIXM: 22.4469
VIVO: 16.0752
VIVE: 1.1828
VIV: 12.9504
VISI: 2.4666
VIS: 126.8717
VIRT: 25.4464
VIRC: 4.0118
VIPS: 7.4747
VIOV: 116.4129
VIOT: 7.0549
VIOO: 135.2443
VIOG: 99.6338
VIIX: 15.8863
VIGI: 60.8621
VIG: 103.2739
VIDI: 21.9055
VICR: 40.2617
VICL: 0.9617
VICI: 21.4665
VIAV: 10.7771
VIAB: 28.437
VIA: 32.8177
VHT: 166.961
VHI: 3.2828
VHC: 4.9551
VGZ: 0.6454
VGT: 178.1878
VGSH: 60.1282
VGR: 10.5375
VGM: 11.5283
VGLT: 74.311
VGK: 51.7636
VGIT: 63.4132
VGI: 11.1809
VG: 9.0406
VFMV: 52.5599
VFMF: 48.2733
VFH: 65.0196
VFC: 84.1536
VEU: 48.6626
VET: 24.0692
VERU: 1.4855
VERI: 5.4339
VER-F: 20.0661
VER: 8.0199
VEON: 2.4639
VEGI: 18.8058
VEEV: 107.2719
VEDL: 11.1338
VECO: 9.8346
VEC: 24.2788
VEACW: 0.4367
VEAC: 10.1332
VEA: 39.6787
VDE: 85.1836
VDC: 135.6773
VCYT: 17.5734
VCV: 10.9481
VCTR: 10.5734
VCSH: 78.6815
VCRA: 39.8207
VCR: 163.3495
VCNX: 3.3666
VCLT: 87.2927
VCIT: 84.4549
VCF: 9.1999
VCEL: 16.6306
VC: 75.3755
VBTX: 26.4121
VBR: 126.0891
VBND: 47.5914
VBLT: 1.3022
VBK: 166.7754
VBIV: 1.6388
VBFC: 22.8066
VBF: 17.6067
VB: 145.555
VAW: 119.574
VAR: 131.5563
VAPO: 16.4759
VALU: 19.7973
VALQ: 25.1869
VALE: 12.3854
VAC: 87.5608
V: 136.5027
UZC: 16.618
UZB: 22.2055
UZA: 24.5266
UYM: 36.3466
UYG: 36.4513
UXIN: 3.477
UWT: 14.145
UWN: 2.3824
UWM: 62.967
UVXY: 58.3749
UVV: 57.4701
UVSP: 23.7581
UVE: 37.7837
UUUU+: 0.8666
UUUU: 2.8898
UUU: 1.1875
UUP: 25.4639
UTX: 118.7636
UTSL: 26.7456
UTSI: 3.4011
UTMD: 88.2684
UTL: 48.4983
UTI: 3.3777
UTHR: 115.763
UTG: 29.856
UTF: 22.9866
UTES: 22.8799
USX: 7.4087
USWSW: 0.67
USWS: 7.4661
USVM: 33.0666
UST: 36.9599
USRT: 46.4453
USPH: 106.2543
USOU: 25.7497
USOI: 21.1785
USOD: 6.5686
USO: 11.4173
USNA: 115.7279
USMV: 54.7446
USMF: 18.5133
USMC: 17.5199
USM: 56.0261
USLV: 80.4185
USLB: 28.3746
USL: 13.9053
USIG: 52.3087
USHY: 31.822
USG: 43.1243
USFR: 24.4339
USFD: 34.2768
USEQ: 17.4266
USEG: 0.8873
USDU: 25.6373
USDP: 10.7507
USD: 30.9053
USCR: 37.3758
USCI: 33.0308
USB-P: 24.2318
USB-O: 23.2511
USB-M: 25.8996
USB-H: 19.4214
USB: 51.1024
USAU: 1.0015
USAT: 5.6783
USAS: 1.6035
USAP: 17.8496
