SampleOutput/sample_vwap_7.txt
XBUY: 16.5865
NRGX: 20.3783
CFG-D: 24.9535
ZYNE: 5.0697
ZYME: 15.3706
ZXZZT: 6.6666
ZVZZT: 9.9905
ZUO: 21.276
ZUMZ: 25.1559
ZTS: 85.2771
ZTR: 9.7814
ZTO: 17.0635
ZSL: 34.8506
ZSAN: 2.2801
ZS: 45.4745
ZROZ: 87.8509
ZOM: 0.7687
ZNH: 34.1479
ZNGA: 4.4816
ZN: 0.4823
ZMLP: 9.0533
ZLAB: 26.894
ZKIN: 1.5452
ZJZZT: 6.6666
ZIXI: 7.4376
ZIV: 66.7847
ZIOP: 2.0793
ZIONW: 10.7799
ZION: 48.2828
ZHOK: 62.24
ZGNX: 42.0444
ZG: 33.0966
ZFGN: 4.2508
ZF: 8.7571
ZEUS: 18.7215
ZEN: 65.5404
ZEAL: 14.1962
ZDGE: 1.2933
ZBRA: 171.2882
ZBIO: 15.9041
ZBH: 107.9574
ZB-H: 16.8499
ZB-G: 23.1711
ZAYO: 26.723
ZAGG: 11.2338
Z: 33.3815
YYY: 17.065
YY: 67.3387
YXI: 19.3333
YVR: 2.2569
YUMC: 35.7936
YUMA: 0.1133
YUM: 93.2548
YTRA: 5.1019
YTEN: 0.8397
YRIV: 2.0735
YRD: 10.9868
YRCW: 5.8348
YPF: 15.8247
YORW: 32.2859
YOGA: 0.5185
YNDX: 33.2539
YMLP: 19.35
YMLI: 8.2466
YMAB: 19.7718
YLDE: 18.3266
YLCO: 12.1471
YINN: 21.7944
YIN: 6.9543
YI: 9.0051
YGYI: 7.2897
YEXT: 15.0456
YETI: 16.7907
YELP: 36.2295
YCS: 61.8867
YAO: 20.1333
YANG: 51.841
Y: 624.0754
XYL: 71.3078
XYF: 5.3974
XXII: 2.2967
XWEB: 82.2619
XTN: 39.7815
XTL: 65.0421
XT: 35.6939
XSW: 79.3428
XSPA: 0.1829
XSOE: 27.1775
XSLV: 45.8279
XSD: 69.8576
XRX: 27.9101
XRT: 44.0373
XRLV: 22.7399
XRAY: 41.4186
XPP: 65.7765
XPO: 61.6576
XPL: 0.184
XPH: 38.516
XPER: 21.1471
XOP: 30.7157
XONE: 8.428
XON: 7.5907
XOMA: 12.0322
XOM: 72.0734
XOG: 4.0937
XNTK: 61.4135
XNET: 3.4073
XNCR: 32.5954
XMLV: 45.8922
XME: 30.1945
XLY: 107.3302
XLV: 89.0774
XLU: 53.5285
XLRN: 40.882
XLRE: 33.9567
XLP: 52.306
XLNX: 111.891
XLK: 65.915
XLI: 71.1929
XLG: 186.7104
XLF: 25.9761
XLE: 63.0868
XLC: 44.0239
XLB: 54.0352
XKST: 26.5
XITK: 92.5633
XIN: 4.7648
XHS: 45.6399
XHR: 18.6303
XHE: 72.6913
XHB: 35.7905
XGTI: 0.3686
XFLT: 8.4626
XES: 10.9566
XERS: 14.9216
XENT: 29.0877
XENE: 7.991
XELB: 1.1931
XELA: 3.596
XEL: 50.9775
XEC: 75.9679
XCEM: 17.2466
XBIT: 6.4452
XBIO: 2.1289
XBI: 81.1667
XAR: 88.8063
XAN-C: 21.6015
XAN: 10.5034
X: 22.2584
WYY: 0.4343
WYNN: 120.1151
WYND: 42.4502
WY: 26.1501
WWW: 33.9694
WWR: 0.1476
WWE: 82.6305
WWD: 86.0856
WVVIP: 3.0799
WVVI: 4.7066
WVFC: 9.6733
WVE: 35.692
WUBA: 61.277
WU: 18.2818
WTW: 31.7191
WTTR: 8.6074
WTT: 1.1133
WTS: 73.5983
WTRH: 12.139
WTR: 34.315
WTMF: 25.5999
WTM: 891.6478
WTIU: 13.6861
WTID: 9.7636
WTI: 5.0884
WTFCM: 26.5773
WTFC: 72.3954
WTER: 3.4934
WTBA: 21.5957
WSTL: 1.8101
WSTG: 7.0733
WST: 105.7145
WSR: 14.2235
WSO: 145.9449
WSM: 52.6307
WSFS: 42.0739
WSC: 10.1662
WSBF: 16.6526
WSBC: 41.5877
WRTC: 3.0098
WRN: 0.7257
WRLSW: 0.1675
WRLSR: 0.2554
WRLS: 10.2
WRLD: 110.8501
WRK: 41.3896
WRI: 28.4649
WRE: 25.171
WRD: 17.2405
WRB-E: 23.9759
WRB-D: 22.1202
WRB-C: 24.7317
WRB-B: 25.2802
WRB: 77.0229
WPX: 12.2902
WPS: 36.6051
WPRT: 1.4822
WPP: 57.7153
WPM: 20.3973
WPG-I: 10.1866
WPG-H: 15.6979
WPG: 5.7588
WPC: 73.9921
WP: 84.4411
WOW: 7.238
WOR: 37.1083
WOOD: 66.2234
WNS: 48.8946
WNEB: 9.2874
WNC: 13.9972
WMT: 94.8942
WMS: 24.9627
WMK: 48.0321
WMGIZ: 0.0046
WMGI: 29.8249
WMC: 9.5841
WMB: 26.9423
WM: 94.6846
WLTW: 160.484
WLL: 28.9357
WLKP: 20.5818
WLK: 76.3888
WLH: 12.4744
WLFC: 36.4478
WLDN: 32.8156
WKHS: 0.8838
WK: 39.3126
WIX: 106.2306
WIW: 10.1848
WIT: 5.494
WISA: 2.6378
WIRE: 53.0728
WIP: 35.9524
WINS: 23.7696
WING: 66.124
WINA: 153.4729
WIN: 2.8645
WILC: 5.4266
WIL: 42.9666
WIFI: 23.1134
WIA: 10.738
WHR: 131.2571
WHLRW: 0.0068
WHLRP: 10.2934
WHLRD: 11.8366
WHLR: 1.6857
WHLM: 5.7191
WHG: 36.4862
WHFBZ: 16.9999
WHF: 13.4777
WHD: 32.4328
WH: 49.617
WGP: 32.7342
WGO: 29.5472
WFT: 0.6413
WFHY: 32.9333
WFE-A: 24.3099
WFC-Y: 24.6365
WFC-X: 22.7781
WFC-W: 24.0964
WFC-V: 25.8164
WFC-T: 22.7477
WFC-R: 23.4464
WFC-Q: 21.3761
WFC-P: 19.5758
WFC-O: 23.0463
WFC-N: 21.9436
WFC-L: 862.4133
WFC: 50.0346
WEYS: 24.1298
WEX: 158.3095
WETF: 6.519
WES: 50.0591
WERN: 33.316
WEN: 17.329
WELL-I: 67.4323
WELL: 76.5787
WEC: 71.1736
WEBK: 19.5866
WEAT: 6.027
WEA: 12.2092
WDRW: 30.5781
WDR: 16.8414
WDIV: 65.36
WDFC: 178.1012
WDC: 43.2606
WDAY: 170.7899
WD: 47.934
WCN: 82.0903
WCHN: 16.8933
WCG: 275.5135
WCFB: 5.5666
WCC: 53.883
WBT: 13.8399
WBS-F: 19.0788
WBS: 55.6114
WBK: 18.2858
WBIY: 15.8999
WBIR: 15.4666
WBII: 16.1399
WBIH: 21.9714
WBIG: 15.5599
WBID: 20.95
WBIB: 21.24
WBC: 113.1836
WBAI: 14.3885
WBA: 71.6568
WB: 58.4435
WATT: 7.3714
WAT: 230.7274
WASH: 51.6358
WAL: 45.446
WAIR: 8.1039
WAGE: 30.8528
WAFD: 29.2392
WABC: 62.8316
WAB: 68.4733
WAAS: 20.9357
W: 107.6797
VZA: 25.3286
VZ: 53.4497
VYMI: 55.395
VYM: 81.8816
VYGR: 10.4788
VXZB: 19.6425
VXXB: 37.6837
VXUS: 50.5608
VXRT: 1.8231
VXF: 109.8255
VWOB: 75.3626
VWO: 41.0061
VVV: 22.3997
VVUS: 4.7166
VVR: 3.8386
VVPR: 0.6466
VVI: 52.1655
VVC: 72.2947
VV: 122.6968
VUZI: 4.0326
VUSE: 28.7751
VUG: 144.0666
VTWV: 91.7892
VTWO: 117.9372
VTWG: 129.0399
VTVT: 2.742
VTV: 104.0385
VTSI: 3.9045
VTR: 63.9019
VTNR: 1.2746
VTN: 12.6204
VTL: 0.1961
VTIQU: 6.8666
VTIP: 48.0938
VTI: 136.9419
VTHR: 117.0298
VTGN: 1.5333
VTEB: 51.1055
VTC: 71.2911
VTA: 10.6992
VT: 70.0541
VSTO: 10.3107
VSTM: 3.1678
VST: 24.9191
VSS: 100.9149
VSMV: 28.1027
VSM: 37.2368
VSLR: 4.0149
VSI: 4.5869
VSH: 19.2271
VSGX: 37.8613
VSEC: 32.1932
VSAT: 61.4305
VRTX: 186.4115
VRTV: 33.3593
VRTU: 47.9614
VRTSP: 76.3837
VRTS: 87.3493
VRSN: 166.5889
VRSK: 117.4878
VRS: 24.707
VRRM: 10.2817
VRP: 22.8194
VRNT: 47.3922
VRNS: 57.4915
VRNA: 4.6377
VRML: 0.6854
VRIG: 20.9926
VREX: 27.9869
VRCA: 11.9586
VRAY: 6.924
VRA: 8.9542
VPV: 12.0651
VPU: 119.7059
VPL: 64.6676
VPG: 32.3144
VOYA: 46.0237
VOXX: 5.2137
VOX: 78.4543
VOT: 131.1366
VOOV: 105.0895
VOOG: 142.2491
VOO: 245.2383
VONV: 103.8067
VONG: 144.1465
VONE: 122.3459
VOE: 103.8241
VOD: 17.8732
VOC: 3.7467
VO: 151.3632
VNTR: 4.7173
VNRX: 2.5571
VNQI: 57.1107
VNQ: 82.483
VNOM: 30.6749
VNO-M: 15.1533
VNO-L: 20.8605
VNO: 68.7098
VNM: 15.8
VNLA: 49.344
VNET: 8.7123
VNE: 29.3439
VNDA: 28.211
VNCE: 11.6927
VMW: 146.2539
VMOT: 16.7608
VMO: 11.6672
VMM: 12.17
VMI: 126.9667
VMC: 101.4293
VMBS: 51.6834
VLYPP: 24.5547
VLYPO: 22.6273
VLY: 10.344
VLUE: 78.6983
VLT: 13.7657
VLRX: 0.3984
VLRS: 7.4229
VLO: 82.7106
VLGEA: 26.1796
VKTXW: 4.4239
VKTX: 8.1692
VKQ: 11.7714
VKI: 10.0855
VJET: 1.3916
VIXY: 30.9886
VIXM: 22.0681
VIVO: 16.1133
VIVE: 1.1767
VIV: 12.9786
VISI: 2.4666
VIS: 129.5872
VIRT: 25.4075
VIRC: 3.8651
VIPS: 7.4805
VIOV: 115.7816
VIOT: 7.2136
VIOO: 137.2049
VIOG: 136.3031
VIIX: 15.8142
VIGI: 61.0357
VIG: 103.3966
VIDI: 24.4104
VICR: 40.2938
VICL: 0.9712
VICI: 21.4515
VIAV: 10.7939
VIAB: 28.497
VIA: 32.937
VHT: 167.2608
VHI: 3.2864
VHC: 5.0151
VGZ: 0.6519
VGT: 178.6797
VGSH: 60.1301
VGR: 10.5578
VGM: 11.7521
VGLT: 74.3205
VGK: 51.7964
VGIT: 63.4774
VGI: 11.0562
VG: 9.0468
VFMV: 75.473
VFMO: 49.1466
VFMF: 48.6265
VFLQ: 50.7866
VFH: 65.0492
VFC: 84.2986
VEU: 48.7304
VET: 24.1285
VERU: 1.4868
VERI: 5.4477
VER-F: 20.0661
VER: 8.0167
VEON: 2.4644
VEGI: 18.8058
VEEV: 107.6544
VEDL: 11.1436
VECO: 9.833
VEC: 24.3386
VEACW: 0.4367
VEAC: 10.1314
VEA: 39.7096
VDE: 85.1952
VDC: 135.6987
VCYT: 17.5734
VCV: 11.0578
VCTR: 10.5785
VCSH: 78.7094
VCRA: 39.8515
VCR: 163.5569
VCNX: 3.3888
VCLT: 87.3342
VCIT: 84.5114
VCF: 9.1999
VCEL: 16.7206
VC: 75.9252
VBTX: 26.4634
VBR: 126.1991
VBND: 47.7905
VBLT: 1.2984
VBK: 167.1681
VBIV: 1.6379
VBFC: 22.8453
VBF: 17.6091
VB: 145.6988
VAW: 119.7296
VAR: 131.9218
VAPO: 16.4734
VAMO: 14.8333
VALU: 20.9965
VALQ: 25.1869
VALE: 12.4161
VAC: 87.6748
V: 136.8211
UZC: 16.618
UZB: 22.2055
UZA: 24.5266
UYM: 36.3466
UYG: 37.0483
UXIN: 3.4621
UWT: 14.1426
UWN: 2.4115
UWM: 62.9808
UVXY: 57.9298
UVV: 57.7943
UVSP: 23.7243
UVE: 37.7936
UUUU+: 0.8666
UUUU: 2.8884
UUU: 1.1875
UUP: 25.4592
UTX: 118.8998
UTSL: 26.9347
UTSI: 3.2483
UTMD: 92.389
UTL: 48.7504
UTI: 3.3651
UTHR: 115.9052
UTG: 29.4428
UTF: 22.9937
UTES: 22.8799
USX: 7.4679
USWSW: 0.67
USWS: 7.555
USVM: 33.0666
UST: 54.6062
USRT: 46.6592
USPH: 106.2875
USOU: 25.7497
USOI: 21.1785
USOD: 5.2835
USO: 11.4163
USNA: 115.527
USMV: 54.8043
USMF: 18.5912
USMC: 17.5199
USM: 56.0332
USLV: 80.6433
USLM: 46.5266
USLB: 28.3746
USL: 13.9051
USIG: 52.6243
USHY: 31.822
USG: 43.1272
USFR: 24.8732
USFD: 34.2301
USEQ: 17.4266
USEG: 0.8869
USDU: 24.7626
USDP: 10.9478
USD: 31.2874
